<?xml version="1.0" ?>
<!-- =================================================================================== -->
<!-- |    This document was autogenerated by xacro from phantomx_turret.urdf.xacro     | -->
<!-- |    EDITING THIS FILE BY HAND IS NOT RECOMMENDED                                 | -->
<!-- =================================================================================== -->
<robot name="phantomx_turret" xmlns:xacro="http://ros.org/wiki/xacro">
  <material name="White">
    <color rgba="0.87 0.90 0.87 1.0"/>
  </material>
  <material name="Black">
    <color rgba="0.08 0.08 0.08 1.0"/>
  </material>
  <material name="Gray">
    <color rgba="0.2 0.2 0.21 1.0"/>
  </material>
  <material name="Green">
    <color rgba="0.22 0.32 0.14 1.0"/>
  </material>
  <link name="base_link"/>
  <joint name="base_mount_joint" type="fixed">
    <origin rpy="1.570795 0 0" xyz="0 0 0"/>
    <parent link="base_link"/>
    <child link="base_mount_link"/>
  </joint>
  <link name="base_mount_link">
    <inertial>
      <mass value="0.21328"/>
      <origin xyz="0.00199427 0.0257168 0.00107065"/>
      <inertia ixx="0.0003798" ixy="-6.70148E-7" ixz="-5.778745E-6" iyy="0.0006116" iyz="-8.17711E-7" izz="0.000379"/>
    </inertial>
    <visual>
      <origin rpy="0 0 0" xyz="0 0 0"/>
      <geometry>
        <mesh filename="package://phantomx_turret/meshes/Base.stl" scale="0.001 0.001 0.001"/>
      </geometry>
      <material name="Gray"/>
    </visual>
    <collision>
      <origin rpy="0 0 0" xyz="-2e-6 0.05785 -9e-6"/>
      <geometry>
        <box size="0.1045 0.0049 0.1045"/>
      </geometry>
    </collision>
    <collision>
      <origin rpy="0 0 0" xyz="-2e-6 0.0329 -9.5e-6"/>
      <geometry>
        <box size="0.086 0.045 0.086929"/>
      </geometry>
    </collision>
    <collision>
      <origin rpy="0 0 0" xyz="-2e-6 0.005139 -9e-6"/>
      <geometry>
        <box size="0.178 0.010522 0.178"/>
      </geometry>
    </collision>
  </link>
  <gazebo reference="base_mount_link">
    <material>Gazebo/Gray</material>
    <selfCollide>true</selfCollide>
    <gravity>true</gravity>
  </gazebo>
  <joint name="pan_servo_joint" type="fixed">
    <origin rpy="-1.570795 0 0" xyz="-2e-6 0.0763 -9e-6"/>
    <parent link="base_mount_link"/>
    <child link="pan_servo_link"/>
  </joint>
  <link name="pan_servo_link">
    <inertial>
      <mass value="0.0546"/>
      <origin xyz="-2.89001e-5 -0.0126033 0.00112682"/>
      <inertia ixx="1.43900e-5" ixy="1.54100e-9" ixz="1.1563e-8" iyy="1.21900e-5" iyz="2.16221e-7" izz="7.768456e-6"/>
    </inertial>
    <visual>
      <origin rpy="0 0 0" xyz="0 0 0"/>
      <geometry>
        <mesh filename="package://phantomx_turret/meshes/AX-12A.stl" scale="0.001 0.001 0.001"/>
      </geometry>
      <material name="Black"/>
    </visual>
    <collision>
      <origin rpy="0 0 0" xyz="0 -0.0135 0.0010025"/>
      <geometry>
        <box size="0.032 0.05 0.040047"/>
      </geometry>
    </collision>
  </link>
  <gazebo reference="pan_servo_link">
    <material>Gazebo/Black</material>
    <selfCollide>true</selfCollide>
    <gravity>true</gravity>
  </gazebo>
  <joint name="pan_F3_joint" type="revolute">
    <origin rpy="0 0 0" xyz="0 0 0.02094"/>
    <axis xyz="0 1 0"/>
    <limit effort="1.5" lower="-2.61799166667" upper="2.61799166667" velocity="11.8912423395"/>
    <dynamics friction="0.13"/>
    <parent link="pan_servo_link"/>
    <child link="pan_F3_link"/>
  </joint>
  <link name="pan_F3_link">
    <inertial>
      <mass value="0.004398"/>
      <origin xyz="2.45363e-17 -2.45363e-17 0.00183916"/>
      <inertia ixx="7.00046e-7" ixy="0" ixz="0" iyy="2.66739e-7" iyz="0" izz="9.31478e-7"/>
    </inertial>
    <visual>
      <origin rpy="0 0 0" xyz="0 0 0"/>
      <geometry>
        <mesh filename="package://phantomx_turret/meshes/F3-Bracket.stl" scale="0.001 0.001 0.001"/>
      </geometry>
      <material name="Gray"/>
    </visual>
    <collision>
      <origin rpy="0 0 0" xyz="0 0 0"/>
      <geometry>
        <box size="0 0 0"/>
      </geometry>
    </collision>
  </link>
  <gazebo reference="pan_F3_link">
    <material>Gazebo/Gray</material>
    <selfCollide>true</selfCollide>
    <gravity>true</gravity>
  </gazebo>
</robot>

